<?xml version='1.0' encoding='UTF-8'?>
<robot name="plane_road">

  <link name="road">

    <visual>
      <geometry>
        <box size="4 80 0.001"/>
      </geometry>

      <material name="asphalt">
<!--        <color rgba="0.2 0.2 0.3 1"/>-->
      </material>

    </visual>

    <collision>
      <geometry>
        <box size="4 80 0.001"/>
      </geometry>
    </collision>

  </link>

  <link name="side">

    <visual>
      <geometry>
        <box size="40 80 0.000001"/>
      </geometry>

      <material name="grass">
        <color rgba="0.5 0.8 0.4 1"/>
      </material>
    </visual>

<!--    <collision>-->
<!--      <geometry>-->
<!--        <box size="20 40 0.0000001"/>-->
<!--      </geometry>-->
<!--    </collision>-->

  </link>


  <joint name="joint1" type="continuous">
    <parent link="road"/>
    <child link="side"/>
    <origin xyz="0 0 0" rpy="0 0 0" />
  </joint>
</robot>